Workbook

Sheet INSTRUCTIONS
B2: FINANCIAL STATEMENTS RATIO ANALYZER
B3: Naicents Ltd | Kenya Financial Consultancy | Client Advisory Tool
B5: PURPOSE
B6: This tool calculates 28 financial ratios from two years of financial statements, organized into five groups: Profitability, Liquidity, Efficiency, Leverage/Solvency, and Valuation. Each ratio includes a benchmark comparison, year-on-year trend, and auto-generated flag (Strong/Acceptable/Caution/Weak). The DASHBOARD provides a one-page executive summary for client presentations. All monetary inputs are in KES thousands (KES '000). No macros.
B8: TABS
B9: INSTRUCTIONS | C9: This tab.
B10: INPUT | C10: Enter all financial data here. Blue-shaded cells only. Two years required.
B11: RATIOS | C11: All 28 ratios auto-calculated with flags, benchmarks, and YoY trends.
B12: DASHBOARD | C12: One-page executive summary with KPI cards, charts, RAG status, and commentary.
B13: BENCHMARKS | C13: Editable benchmark table. Adjust for manufacturing, retail, or services.
B15: HOW TO USE
B16: Step 1 | C16: INPUT tab, cell B5: Enter the company name.
B17: Step 2 | C17: INPUT tab, cells B6/C6: Enter the Current Year and Prior Year period labels.
B18: Step 3 | C18: Enter CY figures in column B and PY figures in column C. Blue cells only.
B19: Step 4 | C19: Confirm the Balance Sheet Check (row 62) shows BALANCED before proceeding.
B20: Step 5 | C20: Open RATIOS tab to review all calculated ratios and flags.
B21: Step 6 | C21: Open DASHBOARD for the executive summary and charts.
B22: Step 7 | C22: Adjust benchmarks on the BENCHMARKS tab for the client's specific industry.
B23: Step 8 | C23: For valuation ratios, enter the market price per share in INPUT!B67.
B25: COLOR GUIDE
B26: Blue text on light-blue cell | C26: Editable input. Enter your data here.
B27: Black text on white cell | C27: Formula result. Do not edit.
B28: Green text on white cell | C28: Cross-sheet formula. Do not edit.
B29: Green background on FLAG cell | C29: Strong — ratio exceeds benchmark comfortably.
B30: Amber background on FLAG cell | C30: Caution — ratio approaching threshold. Monitor closely.
B31: Red background on FLAG cell | C31: Weak — ratio below acceptable range. Action required.
B33: DISCLAIMER
B34: Prepared by Naicents Ltd for analytical and advisory purposes only. Benchmarks are indicative and based on Kenyan SME norms. Adjust on BENCHMARKS tab for industry-specific contexts. This does not constitute audited financial statements. Naicents Ltd accepts no liability for decisions made based on this analysis.

Sheet INPUT
A2: INPUT — CLIENT FINANCIAL DATA
A3: Naicents Ltd | Blue cells are editable inputs | All monetary values in KES '000 (divide actuals by 1,000)
A5: Company Name | B5: Savanna Manufacturing Ltd | D5: Enter the legal name of the client entity.
A6: Reporting Period | B6: FY 2025 | C6: FY 2024 | D6: Current Year label (B) and Prior Year label (C).
A7: Currency / Units | B7: KES '000 | C7: KES '000 | D7: All monetary amounts in thousands of KES.
A9: INCOME STATEMENT
A10: LINE ITEM | B10: CY (KES '000) | C10: PY (KES '000) | D10: Notes
A11: Revenue | B11: 85000 | C11: 72000 | D11: Total turnover / sales for the period
A12: Cost of Sales | B12: 51000 | C12: 43200 | D12: Direct costs of goods sold / cost of production
A13: GROSS PROFIT | B13: =B11-B12 -> 34000 | C13: =C11-C12 -> 28800 | D13: Revenue minus Cost of Sales
A15: Operating Expenses
A16: Salaries & Wages | B16: 12750 | C16: 10800 | D16: Employee salaries, wages, and benefits
A17: Rent | B17: 2550 | C17: 2160 | D17: Premises lease and rent costs
A18: Utilities | B18: 1700 | C18: 1440 | D18: Electricity, water, internet, and fuel
A19: Depreciation & Amortisation | B19: 2125 | C19: 1800 | D19: Non-cash charge on PPE and intangibles
A20: Other Overheads | B20: 3400 | C20: 2880 | D20: Administration, transport, sundry expenses
A21: Total Operating Expenses | B21: =SUM(B16:B20) -> 22525 | C21: =SUM(C16:C20) -> 19080 | D21: Sum of all operating expense lines above
A22: EBIT (Operating Profit) | B22: =B13-B21 -> 11475 | C22: =C13-C21 -> 9720 | D22: Gross Profit minus Total Operating Expenses
A23: Finance Costs | B23: 1870 | C23: 1620 | D23: Interest on loans and other borrowing costs
A24: PROFIT BEFORE TAX | B24: =B22-B23 -> 9605 | C24: =C22-C23 -> 8100 | D24: EBIT minus Finance Costs
A25: Income Tax | B25: 2882 | C25: 2430 | D25: Current year tax charge per income tax computation
A26: PROFIT AFTER TAX (PAT) | B26: =B24-B25 -> 6723 | C26: =C24-C25 -> 5670 | D26: Bottom-line profit after tax
A27: EBITDA | B27: =B22+B19 -> 13600 | C27: =C22+C19 -> 11520 | D27: EBIT plus Depreciation & Amortisation
A29: BALANCE SHEET
A30: LINE ITEM | B30: CY (KES '000) | C30: PY (KES '000) | D30: Notes
A31: Current Assets
A32: Cash & Cash Equivalents | B32: 8500 | C32: 6200 | D32: Bank balances and petty cash
A33: Trade Receivables | B33: 14200 | C33: 12800 | D33: Debtors / amounts owed by customers
A34: Inventory | B34: 11900 | C34: 10600 | D34: Raw materials, WIP, finished goods
A35: Other Current Assets | B35: 2800 | C35: 2400 | D35: Prepayments, other short-term assets
A36: TOTAL CURRENT ASSETS | B36: =SUM(B32:B35) -> 37400 | C36: =SUM(C32:C35) -> 32000
A37: Non-Current Assets
A38: Property, Plant & Equipment (Net) | B38: 32000 | C38: 28500 | D38: PPE net of accumulated depreciation
A39: Intangible Assets | B39: 1500 | C39: 1800 | D39: Goodwill, licenses, software
A40: Other Non-Current Assets | B40: 2200 | C40: 1900 | D40: Long-term deposits, investments
A41: TOTAL NON-CURRENT ASSETS | B41: =SUM(B38:B40) -> 35700 | C41: =SUM(C38:C40) -> 32200
A42: TOTAL ASSETS | B42: =B36+B41 -> 73100 | C42: =C36+C41 -> 64200
A44: Current Liabilities
A45: Trade Payables | B45: 9800 | C45: 8200 | D45: Creditors / amounts owed to suppliers
A46: Short-Term Debt | B46: 5500 | C46: 4800 | D46: Overdrafts and current portion of LTD
...

Sheet RATIOS
A2: RATIO ANALYSIS
A3: =IFERROR("Client: "&INPUT!B5&" | "&INPUT!B6&" vs "&INPUT!C6,"") -> Client: Savanna Manufacturing Ltd | FY 2025 vs FY 2024
A5: RATIO | B5: CURRENT YEAR | C5: PRIOR YEAR | D5: YoY CHANGE | E5: BENCHMARK | F5: FLAG | G5: NOTES
A7: PROFITABILITY
A8: Gross Profit Margin | B8: =IFERROR(INPUT!B13/INPUT!B11,"-") -> 0.4 | C8: =IFERROR(INPUT!C13/INPUT!C11,"-") -> 0.4 | D8: =IFERROR(B8-C8,"-") -> 0 | E8: =IFERROR(INDEX(BENCHMARKS!$B$6:$B$60,MATCH("Gross Profit Margin",BENCHMARKS!$A$6:$A$60,0)),"-") -> 0.35 | F8: =IFERROR(IF(B8>=0.4,"Strong",IF(B8>=0.25,"Acceptable",IF(B8>=0.15,"Caution","Weak"))),"-") -> Strong
A9: Operating (EBIT) Margin | B9: =IFERROR(INPUT!B22/INPUT!B11,"-") -> 0.135 | C9: =IFERROR(INPUT!C22/INPUT!C11,"-") -> 0.135 | D9: =IFERROR(B9-C9,"-") -> 0 | E9: =IFERROR(INDEX(BENCHMARKS!$B$6:$B$60,MATCH("Operating (EBIT) Margin",BENCHMARKS!$A$6:$A$60,0)),"-") -> 0.12 | F9: =IFERROR(IF(B9>=0.15,"Strong",IF(B9>=0.08,"Acceptable",IF(B9>=0.04,"Caution","Weak"))),"-") -> Acceptable
A10: Net Profit Margin | B10: =IFERROR(INPUT!B26/INPUT!B11,"-") -> 0.079094118 | C10: =IFERROR(INPUT!C26/INPUT!C11,"-") -> 0.07875 | D10: =IFERROR(B10-C10,"-") -> 0.00034411765 | E10: =IFERROR(INDEX(BENCHMARKS!$B$6:$B$60,MATCH("Net Profit Margin",BENCHMARKS!$A$6:$A$60,0)),"-") -> 0.08 | F10: =IFERROR(IF(B10>=0.1,"Strong",IF(B10>=0.05,"Acceptable",IF(B10>=0.02,"Caution","Weak"))),"-") -> Acceptable
A11: Return on Assets (ROA) | B11: =IFERROR(INPUT!B26/INPUT!B42,"-") -> 0.091969904 | C11: =IFERROR(INPUT!C26/INPUT!C42,"-") -> 0.088317757 | D11: =IFERROR(B11-C11,"-") -> 0.0036521472 | E11: =IFERROR(INDEX(BENCHMARKS!$B$6:$B$60,MATCH("Return on Assets (ROA)",BENCHMARKS!$A$6:$A$60,0)),"-") -> 0.1 | F11: =IFERROR(IF(B11>=0.15,"Strong",IF(B11>=0.08,"Acceptable",IF(B11>=0.04,"Caution","Weak"))),"-") -> Acceptable
A12: Return on Equity (ROE) | B12: =IFERROR(INPUT!B26/INPUT!B59,"-") -> 0.18571823 | C12: =IFERROR(INPUT!C26/INPUT!C59,"-") -> 0.19619377 | D12: =IFERROR(B12-C12,"-") -> -0.01047554 | E12: =IFERROR(INDEX(BENCHMARKS!$B$6:$B$60,MATCH("Return on Equity (ROE)",BENCHMARKS!$A$6:$A$60,0)),"-") -> 0.15 | F12: =IFERROR(IF(B12>=0.2,"Strong",IF(B12>=0.12,"Acceptable",IF(B12>=0.06,"Caution","Weak"))),"-") -> Acceptable
A13: Return on Capital Employed (ROCE) | B13: =IFERROR(INPUT!B22/(INPUT!B42-INPUT!B49),"-") -> 0.21857143 | C13: =IFERROR(INPUT!C22/(INPUT!C42-INPUT!C49),"-") -> 0.20903226 | D13: =IFERROR(B13-C13,"-") -> 0.0095391705 | E13: =IFERROR(INDEX(BENCHMARKS!$B$6:$B$60,MATCH("Return on Capital Employed (ROCE)",BENCHMARKS!$A$6:$A$60,0)),"-") -> 0.12 | F13: =IFERROR(IF(B13>=0.15,"Strong",IF(B13>=0.1,"Acceptable",IF(B13>=0.05,"Caution","Weak"))),"-") -> Strong
A14: EBITDA Margin | B14: =IFERROR(INPUT!B27/INPUT!B11,"-") -> 0.16 | C14: =IFERROR(INPUT!C27/INPUT!C11,"-") -> 0.16 | D14: =IFERROR(B14-C14,"-") -> 0 | E14: =IFERROR(INDEX(BENCHMARKS!$B$6:$B$60,MATCH("EBITDA Margin",BENCHMARKS!$A$6:$A$60,0)),"-") -> 0.18 | F14: =IFERROR(IF(B14>=0.2,"Strong",IF(B14>=0.12,"Acceptable",IF(B14>=0.07,"Caution","Weak"))),"-") -> Acceptable
A15: Cost-to-Income Ratio | B15: =IFERROR(INPUT!B21/INPUT!B11,"-") -> 0.265 | C15: =IFERROR(INPUT!C21/INPUT!C11,"-") -> 0.265 | D15: =IFERROR(B15-C15,"-") -> 0 | E15: =IFERROR(INDEX(BENCHMARKS!$B$6:$B$60,MATCH("Cost-to-Income Ratio",BENCHMARKS!$A$6:$A$60,0)),"-") -> 0.65 | F15: =IFERROR(IF(B15<=0.55,"Strong",IF(B15<=0.7,"Acceptable",IF(B15<=0.8,"Caution","Weak"))),"-") -> Strong
A17: LIQUIDITY
A18: Current Ratio | B18: =IFERROR(INPUT!B36/INPUT!B49,"-") -> 1.815534 | C18: =IFERROR(INPUT!C36/INPUT!C49,"-") -> 1.8079096 | D18: =IFERROR(B18-C18,"-") -> 0.0076243761 | E18: =IFERROR(INDEX(BENCHMARKS!$B$6:$B$60,MATCH("Current Ratio",BENCHMARKS!$A$6:$A$60,0)),"-") -> 1.5 | F18: =IFERROR(IF(B18>=2,"Strong",IF(B18>=1.5,"Acceptable",IF(B18>=1,"Caution","Weak"))),"-") -> Acceptable
A19: Quick Ratio (Acid Test) | B19: =IFERROR((INPUT!B36-INPUT!B34)/INPUT!B49,"-") -> 1.2378641 | C19: =IFERROR((INPUT!C36-INPUT!C34)/INPUT!C49,"-") -> 1.2090395 | D19: =IFERROR(B19-C19,"-") -> 0.02882453 | E19: =IFERROR(INDEX(BENCHMARKS!$B$6:$B$60,MATCH("Quick Ratio (Acid Test)",BENCHMARKS!$A$6:$A$60,0)),"-") -> 1 | F19: =IFERROR(IF(B19>=1.5,"Strong",IF(B19>=0.8,"Acceptable",IF(B19>=0.5,"Caution","Weak"))),"-") -> Acceptable
A20: Cash Ratio | B20: =IFERROR(INPUT!B32/INPUT!B49,"-") -> 0.41262136 | C20: =IFERROR(INPUT!C32/INPUT!C49,"-") -> 0.35028249 | D20: =IFERROR(B20-C20,"-") -> 0.062338873 | E20: =IFERROR(INDEX(BENCHMARKS!$B$6:$B$60,MATCH("Cash Ratio",BENCHMARKS!$A$6:$A$60,0)),"-") -> 0.3 | F20: =IFERROR(IF(B20>=0.5,"Strong",IF(B20>=0.2,"Acceptable",IF(B20>=0.1,"Caution","Weak"))),"-") -> Acceptable
A21: Operating Cash Conversion | B21: =IFERROR(INPUT!B26/INPUT!B11,"-") -> 0.079094118 | C21: =IFERROR(INPUT!C26/INPUT!C11,"-") -> 0.07875 | D21: =IFERROR(B21-C21,"-") -> 0.00034411765 | E21: =IFERROR(INDEX(BENCHMARKS!$B$6:$B$60,MATCH("Operating Cash Conversion",BENCHMARKS!$A$6:$A$60,0)),"-") -> 0.07 | F21: =IFERROR(IF(B21>=0.1,"Strong",IF(B21>=0.05,"Acceptable",IF(B21>=0.02,"Caution","Weak"))),"-") -> Acceptable
A23: EFFICIENCY
A24: Debtor Days (DSO) | B24: =IFERROR(INPUT!B33/INPUT!B11*365,"-") -> 60.976471 | C24: =IFERROR(INPUT!C33/INPUT!C11*365,"-") -> 64.888889 | D24: =IFERROR(B24-C24,"-") -> -3.9124183 | E24: =IFERROR(INDEX(BENCHMARKS!$B$6:$B$60,MATCH("Debtor Days (DSO)",BENCHMARKS!$A$6:$A$60,0)),"-") -> 45 | F24: =IFERROR(IF(B24<=30,"Strong",IF(B24<=45,"Acceptable",IF(B24<=60,"Caution","Weak"))),"-") -> Weak
A25: Creditor Days (DPO) | B25: =IFERROR(INPUT!B45/INPUT!B12*365,"-") -> 70.137255 | C25: =IFERROR(INPUT!C45/INPUT!C12*365,"-") -> 69.282407 | D25: =IFERROR(B25-C25,"-") -> 0.85484749 | E25: =IFERROR(INDEX(BENCHMARKS!$B$6:$B$60,MATCH("Creditor Days (DPO)",BENCHMARKS!$A$6:$A$60,0)),"-") -> 45 | F25: =IFERROR(IF(B25>=60,"Strong",IF(B25>=45,"Acceptable",IF(B25>=30,"Caution","Weak"))),"-") -> Strong
A26: Inventory Days | B26: =IFERROR(INPUT!B34/INPUT!B12*365,"-") -> 85.166667 | C26: =IFERROR(INPUT!C34/INPUT!C12*365,"-") -> 89.560185 | D26: =IFERROR(B26-C26,"-") -> -4.3935185 | E26: =IFERROR(INDEX(BENCHMARKS!$B$6:$B$60,MATCH("Inventory Days",BENCHMARKS!$A$6:$A$60,0)),"-") -> 60 | F26: =IFERROR(IF(B26<=45,"Strong",IF(B26<=60,"Acceptable",IF(B26<=90,"Caution","Weak"))),"-") -> Caution
A27: Cash Conversion Cycle (CCC) | B27: =IFERROR(INPUT!B33/INPUT!B11*365+INPUT!B34/INPUT!B12*365-INPUT!B45/INPUT!B12*365,"-") -> 76.005882 | C27: =IFERROR(INPUT!C33/INPUT!C11*365+INPUT!C34/INPUT!C12*365-INPUT!C45/INPUT!C12*365,"-") -> 85.166667 | D27: =IFERROR(B27-C27,"-") -> -9.1607843 | E27: =IFERROR(INDEX(BENCHMARKS!$B$6:$B$60,MATCH("Cash Conversion Cycle (CCC)",BENCHMARKS!$A$6:$A$60,0)),"-") -> 60 | F27: =IFERROR(IF(B27<=45,"Strong",IF(B27<=70,"Acceptable",IF(B27<=100,"Caution","Weak"))),"-") -> Caution
A28: Asset Turnover | B28: =IFERROR(INPUT!B11/INPUT!B42,"-") -> 1.1627907 | C28: =IFERROR(INPUT!C11/INPUT!C42,"-") -> 1.1214953 | D28: =IFERROR(B28-C28,"-") -> 0.041295371 | E28: =IFERROR(INDEX(BENCHMARKS!$B$6:$B$60,MATCH("Asset Turnover",BENCHMARKS!$A$6:$A$60,0)),"-") -> 1.2 | F28: =IFERROR(IF(B28>=1.5,"Strong",IF(B28>=0.8,"Acceptable",IF(B28>=0.5,"Caution","Weak"))),"-") -> Acceptable
A29: Revenue per Employee (KES '000) | B29: =IFERROR(INPUT!B11/INPUT!B68,"-") -> 1000 | C29: =IFERROR(INPUT!C11/INPUT!C68,"-") -> 900 | D29: =IFERROR(B29-C29,"-") -> 100 | E29: =IFERROR(INDEX(BENCHMARKS!$B$6:$B$60,MATCH("Revenue per Employee (KES '000)",BENCHMARKS!$A$6:$A$60,0)),"-") -> 1000 | F29: =IFERROR(IF(B29>=1500,"Strong",IF(B29>=800,"Acceptable",IF(B29>=400,"Caution","Weak"))),"-") -> Acceptable
A31: LEVERAGE / SOLVENCY
A32: Debt-to-Equity Ratio | B32: =IFERROR((INPUT!B46+INPUT!B51)/INPUT!B59,"-") -> 0.55248619 | C32: =IFERROR((INPUT!C46+INPUT!C51)/INPUT!C59,"-") -> 0.71972318 | D32: =IFERROR(B32-C32,"-") -> -0.167237 | E32: =IFERROR(INDEX(BENCHMARKS!$B$6:$B$60,MATCH("Debt-to-Equity Ratio",BENCHMARKS!$A$6:$A$60,0)),"-") -> 1 | F32: =IFERROR(IF(B32<=0.5,"Strong",IF(B32<=1,"Acceptable",IF(B32<=2,"Caution","Weak"))),"-") -> Acceptable
A33: Debt-to-Assets Ratio | B33: =IFERROR((INPUT!B46+INPUT!B51)/INPUT!B42,"-") -> 0.27359781 | C33: =IFERROR((INPUT!C46+INPUT!C51)/INPUT!C42,"-") -> 0.32398754 | D33: =IFERROR(B33-C33,"-") -> -0.050389728 | E33: =IFERROR(INDEX(BENCHMARKS!$B$6:$B$60,MATCH("Debt-to-Assets Ratio",BENCHMARKS!$A$6:$A$60,0)),"-") -> 0.5 | F33: =IFERROR(IF(B33<=0.3,"Strong",IF(B33<=0.5,"Acceptable",IF(B33<=0.7,"Caution","Weak"))),"-") -> Strong
A34: Interest Coverage Ratio | B34: =IFERROR(INPUT!B22/INPUT!B23,"-") -> 6.1363636 | C34: =IFERROR(INPUT!C22/INPUT!C23,"-") -> 6 | D34: =IFERROR(B34-C34,"-") -> 0.13636364 | E34: =IFERROR(INDEX(BENCHMARKS!$B$6:$B$60,MATCH("Interest Coverage Ratio",BENCHMARKS!$A$6:$A$60,0)),"-") -> 3 | F34: =IFERROR(IF(B34>=5,"Strong",IF(B34>=2.5,"Acceptable",IF(B34>=1.5,"Caution","Weak"))),"-") -> Strong
A35: Net Debt (KES '000) | B35: =IFERROR(INPUT!B46+INPUT!B51-INPUT!B32,"-") -> 11500 | C35: =IFERROR(INPUT!C46+INPUT!C51-INPUT!C32,"-") -> 14600 | D35: =IFERROR(B35-C35,"-") -> -3100 | E35: =IFERROR(INDEX(BENCHMARKS!$B$6:$B$60,MATCH("Net Debt (KES '000)",BENCHMARKS!$A$6:$A$60,0)),"-") -> N/A | F35: =IFERROR(IF(B35<=0,"Net Cash ✓",IF(B35<=15000,"Acceptable","Caution")),"-") -> Acceptable
A36: Net Debt to EBITDA | B36: =IFERROR((INPUT!B46+INPUT!B51-INPUT!B32)/INPUT!B27,"-") -> 0.84558824 | C36: =IFERROR((INPUT!C46+INPUT!C51-INPUT!C32)/INPUT!C27,"-") -> 1.2673611 | D36: =IFERROR(B36-C36,"-") -> -0.42177288 | E36: =IFERROR(INDEX(BENCHMARKS!$B$6:$B$60,MATCH("Net Debt to EBITDA",BENCHMARKS!$A$6:$A$60,0)),"-") -> 2.5 | F36: =IFERROR(IF(B36<=1.5,"Strong",IF(B36<=3,"Acceptable",IF(B36<=4.5,"Caution","Weak"))),"-") -> Strong
A37: Equity Multiplier | B37: =IFERROR(INPUT!B42/INPUT!B59,"-") -> 2.019337 | C37: =IFERROR(INPUT!C42/INPUT!C59,"-") -> 2.2214533 | D37: =IFERROR(B37-C37,"-") -> -0.20211627 | E37: =IFERROR(INDEX(BENCHMARKS!$B$6:$B$60,MATCH("Equity Multiplier",BENCHMARKS!$A$6:$A$60,0)),"-") -> 2 | F37: =IFERROR(IF(B37<=2,"Strong",IF(B37<=3,"Acceptable",IF(B37<=4,"Caution","Weak"))),"-") -> Acceptable
A39: VALUATION
A40: Earnings per Share (EPS) | B40: =IFERROR(INPUT!B26/INPUT!B66,"-") -> 6.723 | C40: =IFERROR(INPUT!C26/INPUT!C66,"-") -> 5.67 | D40: =IFERROR(B40-C40,"-") -> 1.053 | E40: =IFERROR(INDEX(BENCHMARKS!$B$6:$B$60,MATCH("Earnings per Share (EPS)",BENCHMARKS!$A$6:$A$60,0)),"-") -> N/A | F40: =IFERROR(IF(B40>0,"Profitable","Loss"),"-") -> Profitable
A41: Price-to-Earnings (P/E) | B41: =IFERROR(INPUT!B67*INPUT!B66/INPUT!B26,"-") -> 6.6934404 | C41: =IFERROR(INPUT!C67*INPUT!C66/INPUT!C26,"-") -> 6.70194 | D41: =IFERROR(B41-C41,"-") -> -0.0084996069 | E41: =IFERROR(INDEX(BENCHMARKS!$B$6:$B$60,MATCH("Price-to-Earnings (P/E)",BENCHMARKS!$A$6:$A$60,0)),"-") -> 10 | F41: =IFERROR(IF(B41<=8,"Strong",IF(B41<=15,"Acceptable",IF(B41<=25,"Caution","Weak"))),"-") -> Strong
A42: Price-to-Book (P/B) | B42: =IFERROR(INPUT!B67*INPUT!B66/INPUT!B59,"-") -> 1.2430939 | C42: =IFERROR(INPUT!C67*INPUT!C66/INPUT!C59,"-") -> 1.3148789 | D42: =IFERROR(B42-C42,"-") -> -0.07178497 | E42: =IFERROR(INDEX(BENCHMARKS!$B$6:$B$60,MATCH("Price-to-Book (P/B)",BENCHMARKS!$A$6:$A$60,0)),"-") -> 1.5 | F42: =IFERROR(IF(B42>=2,"Strong",IF(B42>=1,"Acceptable",IF(B42>=0.5,"Caution","Weak"))),"-") -> Acceptable
A43: Dividend Yield | B43: "-" | C43: "-" | D43: =IFERROR(B43-C43,"-") -> - | E43: =IFERROR(INDEX(BENCHMARKS!$B$6:$B$60,MATCH("Dividend Yield",BENCHMARKS!$A$6:$A$60,0)),"-") -> N/A | F43: "-"
A44: Note: Valuation ratios require market price per share in INPUT!B67. EPS = PAT / Shares (KES per share). P/B = Market Cap / Total Equity.

Sheet DASHBOARD
B2: FINANCIAL ANALYSIS DASHBOARD
B3: =IFERROR("Client: "&INPUT!B5&" | "&INPUT!B6&" vs "&INPUT!C6,"") -> Client: Savanna Manufacturing Ltd | FY 2025 vs FY 2024
B5: KEY PERFORMANCE INDICATORS
B6: Revenue (KES '000) | E6: Gross Profit Margin | H6: Net Profit Margin
B7: =IFERROR(INPUT!B11,"-") -> 85000 | C7: =IFERROR(IF(INPUT!B11>INPUT!C11," ▲"," ▼")," ") -> ▲ | E7: =IFERROR(RATIOS!B8,"-") -> 0.4 | F7: =IFERROR(IF(RATIOS!B8>RATIOS!C8," ▲"," ▼")," ") -> ▼ | H7: =IFERROR(RATIOS!B10,"-") -> 0.079094118 | I7: =IFERROR(IF(RATIOS!B10>RATIOS!C10," ▲"," ▼")," ") -> ▲
B9: Current Ratio | E9: Return on Equity (ROE) | H9: Interest Coverage
B10: =IFERROR(RATIOS!B18,"-") -> 1.815534 | C10: =IFERROR(IF(RATIOS!B18>RATIOS!C18," ▲"," ▼")," ") -> ▲ | E10: =IFERROR(RATIOS!B12,"-") -> 0.18571823 | F10: =IFERROR(IF(RATIOS!B12>RATIOS!C12," ▲"," ▼")," ") -> ▼ | H10: =IFERROR(RATIOS!B34,"-") -> 6.1363636 | I10: =IFERROR(IF(RATIOS!B34>RATIOS!C34," ▲"," ▼")," ") -> ▲
B12: HEALTH STATUS BY RATIO GROUP
B13: Ratio Group | E13: Status | F13: Auto-Commentary
B14: PROFITABILITY | E14: =IFERROR(IF(RATIOS!F8="Strong","STRONG",IF(RATIOS!F8="Acceptable","ACCEPTABLE",IF(RATIOS!F8="Caution","CAUTION","REVIEW"))),"N/A") -> STRONG | F14: =IFERROR(IF(AND(RATIOS!B8>=0.3,RATIOS!B10>=0.05),"Strong profitability. GP margin "&TEXT(RATIOS!B8,"0.0%")&" and NP margin "&TEXT(RATIOS!B10,"0.0%")&".",IF(RATIOS!B8>=0.2,"Profitability is moderate. GP margin "&TEXT(RATIOS!B8,"0.0%")&". Review overhead structure.","Profitability under pressure. GP margin "&TEXT(RATIOS!B8,"0.0%")&". Urgent cost review required.")),"-") -> Strong profitability. GP margin 40.0% and NP margin 7.9%.
B15: LIQUIDITY | E15: =IFERROR(IF(RATIOS!F18="Strong","STRONG",IF(RATIOS!F18="Acceptable","ACCEPTABLE",IF(RATIOS!F18="Caution","CAUTION","REVIEW"))),"N/A") -> ACCEPTABLE | F15: =IFERROR(IF(RATIOS!B18>=1.5,"Liquidity position is healthy. Current ratio "&TEXT(RATIOS!B18,"0.00")&"x, above 1.5x benchmark.",IF(RATIOS!B18>=1,"Liquidity is adequate but below target. Monitor cash flow closely. Current ratio "&TEXT(RATIOS!B18,"0.00")&"x.","Liquidity risk — current ratio "&TEXT(RATIOS!B18,"0.00")&"x below 1.0x. Immediate working capital review needed.")),"-") -> Liquidity position is healthy. Current ratio 1.82x, above 1.5x benchmark.
B16: EFFICIENCY | E16: =IFERROR(IF(RATIOS!F24="Strong","STRONG",IF(RATIOS!F24="Acceptable","ACCEPTABLE",IF(RATIOS!F24="Caution","CAUTION","REVIEW"))),"N/A") -> REVIEW | F16: =IFERROR(IF(RATIOS!B27<=60,"Working capital efficiency is strong. CCC "&TEXT(RATIOS!B27,"0")&" days.",IF(RATIOS!B27<=90,"Working capital cycle "&TEXT(RATIOS!B27,"0")&" days — review debtor collections and inventory.","Cash conversion cycle of "&TEXT(RATIOS!B27,"0")&" days is extended. Tighten credit terms and stock management.")),"-") -> Working capital cycle 76 days — review debtor collections and inventory.
B17: LEVERAGE / SOLVENCY | E17: =IFERROR(IF(RATIOS!F34="Strong","STRONG",IF(RATIOS!F34="Acceptable","ACCEPTABLE",IF(RATIOS!F34="Caution","CAUTION","REVIEW"))),"N/A") -> STRONG | F17: =IFERROR(IF(RATIOS!B34>=3,"Leverage is manageable. Interest coverage "&TEXT(RATIOS!B34,"0.0")&"x — comfortable above 3x threshold.",IF(RATIOS!B34>=1.5,"Interest coverage "&TEXT(RATIOS!B34,"0.0")&"x — within acceptable range but approaching minimum.","Interest coverage "&TEXT(RATIOS!B34,"0.0")&"x — below 1.5x. Debt servicing risk is elevated.")),"-") -> Leverage is manageable. Interest coverage 6.1x — comfortable above 3x threshold.
B18: VALUATION | E18: =IFERROR(IF(RATIOS!F40="Strong","STRONG",IF(RATIOS!F40="Acceptable","ACCEPTABLE",IF(RATIOS!F40="Caution","CAUTION","REVIEW"))),"N/A") -> REVIEW | F18: =IFERROR(IF(RATIOS!B40<=0,"Company is loss-making. Valuation metrics not meaningful.",IF(RATIOS!B41<=15,"P/E of "&TEXT(RATIOS!B41,"0.0")&"x and EPS of KES "&TEXT(RATIOS!B40,"0.00")&" per share — valuation appears reasonable.","P/E of "&TEXT(RATIOS!B41,"0.0")&"x — premium to sector norms. Confirm earnings quality.")),"-") -> P/E of 6.7x and EPS of KES 6.72 per share — valuation appears reasonable.
L30: Metric | M30: CY | N30: PY
L31: GP Margin | M31: =RATIOS!B8 -> 0.4 | N31: =RATIOS!C8 -> 0.4
L32: EBIT Margin | M32: =RATIOS!B9 -> 0.135 | N32: =RATIOS!C9 -> 0.135
B33: Charts auto-refresh when INPUT data changes. Flag colours: Green = Strong, Blue = Acceptable, Amber = Caution, Red = Weak. | L33: NP Margin | M33: =RATIOS!B10 -> 0.079094118 | N33: =RATIOS!C10 -> 0.07875
L35: Ratio | M35: Actual | N35: Benchmark
L36: Current Ratio | M36: =IFERROR(RATIOS!B18,0) -> 1.815534 | N36: =IFERROR(RATIOS!E18,0) -> 1.5
L37: Quick Ratio | M37: =IFERROR(RATIOS!B19,0) -> 1.2378641 | N37: =IFERROR(RATIOS!E19,0) -> 1
L38: Cash Ratio | M38: =IFERROR(RATIOS!B20,0) -> 0.41262136 | N38: =IFERROR(RATIOS!E20,0) -> 0.3
L39: D/E Ratio | M39: =IFERROR(RATIOS!B32,0) -> 0.55248619 | N39: =IFERROR(RATIOS!E32,0) -> 1
L40: D/A Ratio | M40: =IFERROR(RATIOS!B33,0) -> 0.27359781 | N40: =IFERROR(RATIOS!E33,0) -> 0.5
L41: Int. Coverage | M41: =IFERROR(RATIOS!B34,0) -> 6.1363636 | N41: =IFERROR(RATIOS!E34,0) -> 3

Sheet BENCHMARKS
A2: BENCHMARKS — EDITABLE REFERENCE TABLE
A3: Adjust column B values to match the client's industry. Column B is referenced live by the RATIOS tab.
A4: Percentage ratios: enter as decimals (0.35 = 35%). Multiples and days: enter as numbers. Enter N/A rows as text where no numeric benchmark applies.
A5: Ratio Name | B5: Benchmark Value | C5: Kenya SME Range | D5: General Industry Benchmark | E5: Notes & Interpretation Guidance
A6: Gross Profit Margin | B6: 0.35 | C6: 25%–45% | D6: 30%–50% | E6: Higher for value-add manufacturing. Min 25% to cover overheads.
A7: Operating (EBIT) Margin | B7: 0.12 | C7: 8%–18% | D7: 10%–20% | E7: Below 8% suggests overhead pressure. Target 12%+ for SMEs.
A8: Net Profit Margin | B8: 0.08 | C8: 5%–15% | D8: 7%–15% | E8: Below 5% is a red flag for sustainability.
A9: Return on Assets (ROA) | B9: 0.1 | C9: 8%–15% | D9: 10%–18% | E9: Measures efficiency of asset deployment. >10% is healthy.
A10: Return on Equity (ROE) | B10: 0.15 | C10: 12%–25% | D10: 15%–25% | E10: Shareholders expect minimum 15% return in Kenya.
A11: Return on Capital Employed (ROCE) | B11: 0.12 | C11: 10%–20% | D11: 12%–22% | E11: Capital employed = Total Assets minus Current Liabilities.
A12: EBITDA Margin | B12: 0.18 | C12: 12%–22% | D12: 15%–25% | E12: Key metric for lenders. Below 12% may trigger covenants.
A13: Cost-to-Income Ratio | B13: 0.65 | C13: 55%–75% | D13: 50%–70% | E13: Lower is better. Above 80% indicates structural cost issue.
A14: Current Ratio | B14: 1.5 | C14: 1.2x–2.0x | D14: 1.5x–2.5x | E14: Below 1.0x means inability to meet short-term obligations.
A15: Quick Ratio (Acid Test) | B15: 1 | C15: 0.8x–1.5x | D15: 1.0x–2.0x | E15: Excludes inventory. Below 0.8x is a liquidity warning.
A16: Cash Ratio | B16: 0.3 | C16: 0.2x–0.5x | D16: 0.3x–0.8x | E16: Pure cash coverage. Context-dependent by industry.
A17: Operating Cash Conversion | B17: 0.07 | C17: 5%–12% | D17: 7%–15% | E17: PAT/Revenue proxy. Indicates quality of earnings.
... A26: Interest Coverage Ratio | B26: 3 | C26: 2.5x–5.0x | D26: 3.0x–6.0x | E26: Below 2.0x is a default risk signal for Kenyan banks.
A27: Net Debt (KES '000) | B27: N/A | C27: Context-specific | D27: N/A | E27: Negative = net cash position (favourable).
A28: Net Debt to EBITDA | B28: 2.5 | C28: 1.0x–3.0x | D28: 1.5x–3.5x | E28: Below 2.0x comfortable. Above 4.0x is distress.
A29: Equity Multiplier | B29: 2 | C29: 1.5x–3.0x | D29: 1.5x–3.0x | E29: Higher = more debt financing. DuPont component.
A30: Earnings per Share (EPS) | B30: N/A | C30: N/A | D30: N/A | E30: In KES. Depends on sector and market expectations.
A31: Price-to-Earnings (P/E) | B31: 10 | C31: 6x–15x | D31: 8x–20x | E31: Kenyan NSE SMEs typically trade at 6x–12x P/E.
A32: Price-to-Book (P/B) | B32: 1.5 | C32: 0.8x–2.5x | D32: 1.0x–3.0x | E32: Below 1.0x may indicate undervaluation.
A33: Dividend Yield | B33: N/A | C33: N/A | D33: N/A | E33: Depends on dividend policy. N/A if no dividend paid.
A34: Industry Guide — Manufacturing: higher inventory days (60–90), GP margin 35–50%. Retail: low inventory days (20–45), GP margin 20–35%, asset turnover 2x–4x. Services: minimal inventory, GP margin 50–70%, focus on DSO and Revenue per Employee.
